<?xml version="1.0" ?>
<!-- =================================================================================== -->
<!-- |    This document was autogenerated by xacro from Ackermann_robot.urdf.xacro     | -->
<!-- |    EDITING THIS FILE BY HAND IS NOT RECOMMENDED                                 | -->
<!-- =================================================================================== -->
<robot name="Ackermann_robot">
  <!--<link name="base_link" />-->
  <!--<xacro:macro name="chassi_link" params="name">-->
  <!--</xacro:macro>-->
  <!--<xacro:chassi_link name="chassi_link"/>-->
  <material name="base_color">
    <color rgba="0.8 0.8 0.8 1.0"/>
  </material>
  <link name="base_link"/>
  <link name="chassi_link">
    <inertial>
      <origin rpy="0 0 0" xyz="0 0 0"/>
      <mass value="2.0"/>
      <inertia ixx="0.001" ixy="0" ixz="0" iyy="0.001" iyz="0" izz="0.001"/>
    </inertial>
    <visual name="Base">
      <origin rpy="0 -3.14159 -0.00587" xyz="-0.00055 -0.06897 0.06435"/>
      <geometry>
        <mesh filename="package://ackermann_vehicle_description/robot/meshes/stl/Base.stl" scale="1.0 1.0 1.0"/>
      </geometry>
      <material name="base_color"/>
    </visual>
    <collision name="Base_col">
      <origin rpy="0 3.14159 -0.00587" xyz="-0.00102 -0.09748 0.0092"/>
      <geometry>
        <box size="0.22043 0.27703 0.12452"/>
      </geometry>
    </collision>
  </link>
  <link name="base_link_front">
    </link>
  <joint name="chassi_link_joint" type="fixed">
    <origin rpy="0 0 0" xyz="0 0 0"/>
    <parent link="base_link"/>
    <child link="chassi_link"/>
  </joint>
  <joint name="base_link_front_joint" type="fixed">
    <origin rpy="0 0 0" xyz="0 -0.21396 0"/>
    <parent link="base_link"/>
    <child link="base_link_front"/>
  </joint>
  <material name="pneu_color">
    <color rgba="0.0 0.0 0.0 1.0"/>
  </material>
  <link name="link_wheel_front_left">
    <inertial>
      <origin rpy="0 0 0" xyz="0 0 0"/>
      <mass value="0.15"/>
      <inertia ixx="0.001" ixy="0" ixz="0" iyy="0.001" iyz="0" izz="0.001"/>
    </inertial>
    <visual name="wheel_front_left">
      <origin rpy="-1.57081 2e-05 -2.01041" xyz="0 0 0"/>
      <geometry>
        <mesh filename="package://ackermann_vehicle_description/robot/meshes/stl/wheel_front_left.stl" scale="1.0 1.0 1.0"/>
      </geometry>
      <material name="pneu_color"/>
    </visual>
    <collision name="wheel_front_left_col">
      <origin rpy="-1e-05 2e-05 -2.01041" xyz="0 0 0"/>
      <geometry>
        <cylinder length="0.05" radius="0.05"/>
      </geometry>
    </collision>
  </link>
  <link name="link_wheel_front_right">
    <inertial>
      <origin rpy="0 0 0" xyz="0 0 0"/>
      <mass value="0.15"/>
      <inertia ixx="0.001" ixy="0" ixz="0" iyy="0.001" iyz="0" izz="0.001"/>
    </inertial>
    <visual name="wheel_front_right">
      <origin rpy="-1.57079 -2e-05 -2.01041" xyz="0 0 0"/>
      <geometry>
        <mesh filename="package://ackermann_vehicle_description/robot/meshes/stl/wheel_front_right.stl" scale="1.0 1.0 1.0"/>
      </geometry>
      <material name="pneu_color"/>
    </visual>
    <collision name="wheel_front_right_col">
      <origin rpy="1e-05 -2e-05 -2.01041" xyz="0 0 0"/>
      <geometry>
        <cylinder length="0.05" radius="0.05"/>
      </geometry>
    </collision>
  </link>
  <link name="link_wheel_rear_left">
    <inertial>
      <origin rpy="0 0 0" xyz="0 0 0"/>
      <mass value="0.15"/>
      <inertia ixx="0.001" ixy="0" ixz="0" iyy="0.001" iyz="0" izz="0.001"/>
    </inertial>
    <visual name="wheel_rear_left">
      <origin rpy="-1.5708 0 1.47321" xyz="0 0 0"/>
      <geometry>
        <mesh filename="package://ackermann_vehicle_description/robot/meshes/stl/wheel_rear_left.stl" scale="1.0 1.0 1.0"/>
      </geometry>
      <material name="pneu_color"/>
    </visual>
    <collision name="wheel_rear_left_col">
      <origin rpy="0 0 1.47321" xyz="0 0 0"/>
      <geometry>
        <cylinder length="0.05" radius="0.05"/>
      </geometry>
    </collision>
  </link>
  <link name="link_wheel_rear_right">
    <inertial>
      <origin rpy="0 0 0" xyz="0 0 0"/>
      <mass value="0.15"/>
      <inertia ixx="0.001" ixy="0" ixz="0" iyy="0.001" iyz="0" izz="0.001"/>
    </inertial>
    <visual name="wheel_rear_right">
      <origin rpy="-1.5708 0 -1.61495" xyz="0 0 0"/>
      <geometry>
        <mesh filename="package://ackermann_vehicle_description/robot/meshes/stl/wheel_rear_right.stl" scale="1.0 1.0 1.0"/>
      </geometry>
      <material name="pneu_color"/>
    </visual>
    <collision name="wheel_rear_right_col">
      <origin rpy="0 0 -1.61495" xyz="0 0 0"/>
      <geometry>
        <cylinder length="0.05" radius="0.05"/>
      </geometry>
    </collision>
  </link>
  <!--<link name="link_wheel_front_left">
      <inertial>
        <origin xyz="0 0 0" rpy="0 0 0"/>
        <mass value="0.15"/>
        <inertia ixx="0.001" ixy="0" ixz="0" iyy="0.001" iyz="0" izz="0.001"/>
      </inertial>
      <visual name="wheel_front_left">
        <origin xyz="0 0 0" rpy="-1.57081 2e-05 -2.01041"/>
        <geometry>
          <mesh filename="package://urdf_tutorial/robot/meshes/stl/wheel_front_left.stl" scale="1.0 1.0 1.0"/>
        </geometry>
        <material name="pneu_color"/>
      </visual>
      <collision name="wheel_front_left">
        <origin xyz="0 0 0" rpy="-1e-05 2e-05 -2.01041"/>
        <geometry>
          <cylinder radius="0.05" length="0.05"/>
        </geometry>
      </collision>
    </link>

    <link name="link_wheel_front_right">
      <inertial>
        <origin xyz="0 0 0" rpy="0 0 0"/>
        <mass value="0.15"/>
        <inertia ixx="0.001" ixy="0" ixz="0" iyy="0.001" iyz="0" izz="0.001"/>
      </inertial>
      <visual name="wheel_front_right">
        <origin xyz="0 0 0" rpy="-1.57079 -2e-05 -2.01041"/>
        <geometry>
          <mesh filename="package://urdf_tutorial/robot/meshes/stl/wheel_front_right.stl" scale="1.0 1.0 1.0"/>
        </geometry>
        <material name="pneu_color"/>
      </visual>
      <collision name="wheel_front_right">
        <origin xyz="0 0 0" rpy="1e-05 -2e-05 -2.01041"/>
        <geometry>
          <cylinder radius="0.05" length="0.05"/>
        </geometry>
      </collision>
    </link>

    <link name="link_wheel_rear_left">
      <inertial>
        <origin xyz="0 0 0" rpy="0 0 0"/>
        <mass value="0.15"/>
        <inertia ixx="0.001" ixy="0" ixz="0" iyy="0.001" iyz="0" izz="0.001"/>
      </inertial>
      <visual name="wheel_rear_left">
        <origin xyz="0 0 0" rpy="-1.5708 0 1.47321"/>
        <geometry>
          <mesh filename="package://urdf_tutorial/robot/meshes/stl/wheel_rear_left.stl" scale="1.0 1.0 1.0"/>
        </geometry>
        <material name="pneu_color"/>
      </visual>
      <collision name="wheel_rear_left">
        <origin xyz="0 0 0" rpy="0 0 1.47321"/>
        <geometry>
          <cylinder radius="0.05" length="0.05"/>
        </geometry>
      </collision>
    </link>

    <link name="link_wheel_rear_right">
      <inertial>
        <origin xyz="0 0 0" rpy="0 0 0"/>
        <mass value="0.15"/>
        <inertia ixx="0.001" ixy="0" ixz="0" iyy="0.001" iyz="0" izz="0.001"/>
      </inertial>
      <visual name="wheel_rear_right">
        <origin xyz="0 0 0" rpy="-1.5708 0 -1.61495"/>
        <geometry>
          <mesh filename="package://urdf_tutorial/robot/meshes/stl/wheel_rear_right.stl" scale="1.0 1.0 1.0"/>
        </geometry>
        <material name="pneu_color"/>
      </visual>
      <collision name="wheel_rear_right">
        <origin xyz="0 0 0" rpy="0 0 -1.61495"/>
        <geometry>
          <cylinder radius="0.05" length="0.05"/>
        </geometry>
      </collision>
    </link>-->
  <joint name="joint_wheel_front_left" type="continuous">
    <origin rpy="0 1.5708 0" xyz="0.03048 0 0"/>
    <parent link="link_acker_front_left"/>
    <child link="link_wheel_front_left"/>
    <axis xyz="0 0 1.0"/>
    <limit effort="1.0" velocity="100.0"/>
  </joint>
  <joint name="joint_wheel_front_right" type="continuous">
    <origin rpy="0 -1.5708 0" xyz="-0.03049 0 0"/>
    <parent link="link_acker_front_right"/>
    <child link="link_wheel_front_right"/>
    <axis xyz="0 0 1.0"/>
    <limit effort="1.0" velocity="100.0"/>
  </joint>
  <joint name="joint_wheel_rear_left" type="continuous">
    <origin rpy="0 1.5708 0" xyz="0.13691 0.00033 -0.0371"/>
    <parent link="base_link"/>
    <child link="link_wheel_rear_left"/>
    <axis xyz="0 0 1.0"/>
    <limit effort="1.0" velocity="100.0"/>
  </joint>
  <joint name="joint_wheel_rear_right" type="continuous">
    <origin rpy="0 -1.5708 0" xyz="-0.13691 0.00033 -0.0371"/>
    <parent link="base_link"/>
    <child link="link_wheel_rear_right"/>
    <axis xyz="0 0 1.0"/>
    <limit effort="1.0" velocity="100.0"/>
  </joint>
  <!--<joint name="joint_wheel_front_left" type="continuous">
      <origin xyz="0.03048 0 0" rpy="0 1.5708 0"/>
      <parent link="link_acker_front_left"/>
      <child link="link_wheel_front_left"/>
      <axis xyz="0 0 1.0"/>
      <limit effort="1.0" velocity="100.0"/>
    </joint>

    <joint name="joint_wheel_front_right" type="continuous">
      <origin xyz="-0.03049 0 0" rpy="0 -1.5708 0"/>
      <parent link="link_acker_front_right"/>
      <child link="link_wheel_front_right"/>
      <axis xyz="0 0 1.0"/>
      <limit effort="1.0" velocity="100.0"/>
    </joint>

    <joint name="joint_wheel_rear_left" type="continuous">
      <origin xyz="0.13691 0.00033 -0.0371" rpy="0 1.5708 0"/>
      <parent link="base_link"/>
      <child link="link_wheel_rear_left"/>
      <axis xyz="0 0 1.0"/>
      <limit effort="1.0" velocity="100.0"/>
    </joint>

    <joint name="joint_wheel_rear_right" type="continuous">
      <origin xyz="-0.13691 0.00033 -0.0371" rpy="0 -1.5708 0"/>
      <parent link="base_link"/>
      <child link="link_wheel_rear_right"/>
      <axis xyz="0 0 1.0"/>
      <limit effort="1.0" velocity="100.0"/>
    </joint>-->
  <material name="link_roda_color">
    <color rgba="0.5 0.5 0.5 1.0"/>
  </material>
  <link name="link_acker_front_left">
    <inertial>
      <origin rpy="0 0 0" xyz="0 0 0"/>
      <mass value="0.15"/>
      <inertia ixx="0.002" ixy="0" ixz="0" iyy="0.002" iyz="0" izz="0.002"/>
    </inertial>
    <visual name="encaixe_front_left">
      <origin rpy="0 3.14159 -2e-05" xyz="0.03048 0 0"/>
      <geometry>
        <mesh filename="package://ackermann_vehicle_description/robot/meshes/stl/encaixe_front_left.stl" scale="1.0 1.0 1.0"/>
      </geometry>
      <material name="link_roda_color"/>
    </visual>
  </link>
  <link name="link_acker_front_right">
    <inertial>
      <origin rpy="0 0 0" xyz="0 0 0"/>
      <mass value="0.15"/>
      <inertia ixx="0.002" ixy="0" ixz="0" iyy="0.002" iyz="0" izz="0.002"/>
    </inertial>
    <visual name="encaixe_front_right">
      <origin rpy="0 0 -2e-05" xyz="-0.03049 0 0"/>
      <geometry>
        <mesh filename="package://ackermann_vehicle_description/robot/meshes/stl/encaixe_front_right.stl" scale="1.0 1.0 1.0"/>
      </geometry>
      <material name="link_roda_color"/>
    </visual>
  </link>
  <joint name="joint_acker_front_left" type="revolute">
    <origin rpy="0 0 0" xyz="0.10378 -0.21397 -0.0371"/>
    <parent link="base_link"/>
    <child link="link_acker_front_left"/>
    <axis xyz="0 0 1.0"/>
    <limit effort="5.0" lower="-3.14" upper="3.14" velocity="15.0"/>
  </joint>
  <joint name="joint_acker_front_right" type="revolute">
    <origin rpy="0 0 0" xyz="-0.10624 -0.21396 -0.0371"/>
    <parent link="base_link"/>
    <child link="link_acker_front_right"/>
    <axis xyz="0 0 1.0"/>
    <limit effort="5.0" lower="-3.14" upper="3.14" velocity="15.0"/>
  </joint>
  <material name="imu_color">
    <color rgba="1.0 0.0 0.0 1.0"/>
  </material>
  <link name="imu_link">
    <inertial>
      <origin rpy="0 0 0" xyz="0 0 0"/>
      <mass value="0.001"/>
      <inertia ixx="0.000001" ixy="0" ixz="0" iyy="0.000001" iyz="0" izz="0.000001"/>
    </inertial>
    <visual name="imu">
      <origin rpy="0 0 0" xyz="0 0 0.0005"/>
      <geometry>
        <box size="0.01 0.01 0.001"/>
      </geometry>
      <material name="imu_color"/>
    </visual>
    <collision name="imu_col">
      <origin rpy="0 0 0" xyz="0 0 0.0005"/>
      <geometry>
        <box size="0.01 0.01 0.001"/>
      </geometry>
    </collision>
  </link>
  <joint name="imu_joint" type="fixed">
    <origin rpy="0 0 0" xyz="0 0 0.07077"/>
    <parent link="base_link"/>
    <child link="imu_link"/>
  </joint>
  <!--transmissões dos tornos-->
  <transmission name="acker_front_left_trans">
    <type>transmission_interface/SimpleTransmission</type>
    <actuator name="$acker_front_left_servo">
      <hardwareInterface>hardware_interface/EffortJointInterface</hardwareInterface>
      <mechanicalReduction>1</mechanicalReduction>
    </actuator>
    <joint name="joint_acker_front_left">
      <hardwareInterface>hardware_interface/EffortJointInterface</hardwareInterface>
    </joint>
  </transmission>
  <transmission name="acker_front_right_trans">
    <type>transmission_interface/SimpleTransmission</type>
    <actuator name="$acker_front_right_servo">
      <hardwareInterface>hardware_interface/EffortJointInterface</hardwareInterface>
      <mechanicalReduction>1</mechanicalReduction>
    </actuator>
    <joint name="joint_acker_front_right">
      <hardwareInterface>hardware_interface/EffortJointInterface</hardwareInterface>
    </joint>
  </transmission>
  <gazebo reference="link_acker_front_left">
    <material>Gazebo/Black</material>
  </gazebo>
  <gazebo reference="link_acker_front_right">
    <material>Gazebo/Black</material>
  </gazebo>
  <gazebo reference="imu_link">
    <visual>
      <material>
        <script>
          <uri>file://media/materials/scripts/gazebo.material</uri>
          <name>Gazebo/Black</name>
        </script>
        <emissive>0 0 0 1</emissive>
      </material>
    </visual>
  </gazebo>
  <!--transmissões das rodas-->
  <transmission name="front_left_wheel_trans">
    <type>transmission_interface/SimpleTransmission</type>
    <actuator name="front_left_wheel_motor">
      <hardwareInterface>hardware_interface/EffortJointInterface</hardwareInterface>
      <mechanicalReduction>1</mechanicalReduction>
    </actuator>
    <joint name="joint_wheel_front_left">
      <hardwareInterface>hardware_interface/EffortJointInterface</hardwareInterface>
    </joint>
  </transmission>
  <gazebo reference="link_wheel_front_left">
    <mu1 value="200.0"/>
    <mu2 value="100.0"/>
    <kp value="10000000.0"/>
    <kd value="1.0"/>
    <material>Gazebo/Black</material>
  </gazebo>
  <transmission name="front_right_wheel_trans">
    <type>transmission_interface/SimpleTransmission</type>
    <actuator name="front_right_wheel_motor">
      <hardwareInterface>hardware_interface/EffortJointInterface</hardwareInterface>
      <mechanicalReduction>1</mechanicalReduction>
    </actuator>
    <joint name="joint_wheel_front_right">
      <hardwareInterface>hardware_interface/EffortJointInterface</hardwareInterface>
    </joint>
  </transmission>
  <gazebo reference="link_wheel_front_right">
    <mu1 value="200.0"/>
    <mu2 value="100.0"/>
    <kp value="10000000.0"/>
    <kd value="1.0"/>
    <material>Gazebo/Black</material>
  </gazebo>
  <transmission name="rear_left_wheel_trans">
    <type>transmission_interface/SimpleTransmission</type>
    <actuator name="rear_left_wheel_motor">
      <hardwareInterface>hardware_interface/EffortJointInterface</hardwareInterface>
      <mechanicalReduction>1</mechanicalReduction>
    </actuator>
    <joint name="joint_wheel_rear_left">
      <hardwareInterface>hardware_interface/EffortJointInterface</hardwareInterface>
    </joint>
  </transmission>
  <gazebo reference="link_wheel_rear_left">
    <mu1 value="200.0"/>
    <mu2 value="100.0"/>
    <kp value="10000000.0"/>
    <kd value="1.0"/>
    <material>Gazebo/Black</material>
  </gazebo>
  <transmission name="rear_right_wheel_trans">
    <type>transmission_interface/SimpleTransmission</type>
    <actuator name="rear_right_wheel_motor">
      <hardwareInterface>hardware_interface/EffortJointInterface</hardwareInterface>
      <mechanicalReduction>1</mechanicalReduction>
    </actuator>
    <joint name="joint_wheel_rear_right">
      <hardwareInterface>hardware_interface/EffortJointInterface</hardwareInterface>
    </joint>
  </transmission>
  <gazebo reference="link_wheel_rear_right">
    <mu1 value="200.0"/>
    <mu2 value="100.0"/>
    <kp value="10000000.0"/>
    <kd value="1.0"/>
    <material>Gazebo/Black</material>
  </gazebo>
  <gazebo>
    <plugin filename="libgazebo_ros_control.so" name="gazebo_ros_control">
      <robotNamespace>/</robotNamespace>
      <robotSimType>gazebo_ros_control/DefaultRobotHWSim</robotSimType>
    </plugin>
  </gazebo>
</robot>
